Workbook

Sheet Dashboard
A1: SD GROUP - EMPLOYEE HANDBOOK REGISTER
A2: COMMON SD GROUP - GOVERNANCE DASHBOARD
A3: All figures are live formulas reading the Register tab.
A5: GOVERNANCE SUMMARY
A6: Metric | B6: Value
A7: Total books | B7: =COUNTA(Register!$A$6:$A$35)
A8: Books requiring HR review | B8: =COUNTIF(Register!$I$6:$I$35,"Yes")
A9: Books requiring legal review (legal-sensitive) | B9: =COUNTIF(Register!$J$6:$J$35,"Yes")
A10: Books requiring management approval | B10: =COUNTIF(Register!$K$6:$K$35,"Yes")
A11: Books requiring employee acknowledgement | B11: =COUNTIF(Register!$L$6:$L$35,"Yes")
A12: Books requiring quiz / assessment | B12: =COUNTIF(Register!$M$6:$M$35,"Yes")
A14: PRODUCTION STATUS
A15: Status | B15: Books
A16: Not Started | B16: =COUNTIF(Register!$S$6:$S$35,"Not Started")
A17: Draft Content Created | B17: =COUNTIF(Register!$S$6:$S$35,"Draft Content Created")
A18: HR Review Pending | B18: =COUNTIF(Register!$S$6:$S$35,"HR Review Pending")
A19: HR Approved | B19: =COUNTIF(Register!$S$6:$S$35,"HR Approved")
A20: Legal Review Pending | B20: =COUNTIF(Register!$S$6:$S$35,"Legal Review Pending")
A21: Legal Approved | B21: =COUNTIF(Register!$S$6:$S$35,"Legal Approved")
A22: Management Review Pending | B22: =COUNTIF(Register!$S$6:$S$35,"Management Review Pending")
A23: Management Approved | B23: =COUNTIF(Register!$S$6:$S$35,"Management Approved")
A24: PDF Designed | B24: =COUNTIF(Register!$S$6:$S$35,"PDF Designed")
A25: PDF Final Checked | B25: =COUNTIF(Register!$S$6:$S$35,"PDF Final Checked")
A26: Uploaded to SD Academy | B26: =COUNTIF(Register!$S$6:$S$35,"Uploaded to SD Academy")
A27: Access Tagged | B27: =COUNTIF(Register!$S$6:$S$35,"Access Tagged")
A28: Acknowledgement Campaign Live | B28: =COUNTIF(Register!$S$6:$S$35,"Acknowledgement Campaign Live")
A29: Employee Acknowledgement Completed | B29: =COUNTIF(Register!$S$6:$S$35,"Employee Acknowledgement Completed")
A30: Archived / Superseded | B30: =COUNTIF(Register!$S$6:$S$35,"Archived / Superseded")
A32: ACCESS LEVEL SPREAD
A33: Access band | B33: Books
A34: L1-L5 | B34: =COUNTIF(Register!$F$6:$F$35,"L1-L5")
A35: L2-L5 | B35: =COUNTIF(Register!$F$6:$F$35,"L2-L5")
A36: L3-L5 | B36: =COUNTIF(Register!$F$6:$F$35,"L3-L5")
A37: L4-L5 | B37: =COUNTIF(Register!$F$6:$F$35,"L4-L5")
A38: L5 | B38: =COUNTIF(Register!$F$6:$F$35,"L5")
A40: WEBSITE UPLOAD PROGRESS
A41: Upload step | B41: Done
A42: 1. File Uploaded | B42: =COUNTIF(Upload_Checklist!$J$19:$J$48,"Done")&" / 30"
A43: 2. Folder Path Verified | B43: =COUNTIF(Upload_Checklist!$K$19:$K$48,"Done")&" / 30"
A44: 3. Access Tags Applied | B44: =COUNTIF(Upload_Checklist!$L$19:$L$48,"Done")&" / 30"
...

Sheet Register
A1: SD GROUP - EMPLOYEE HANDBOOK REGISTER
A2: COMMON SD GROUP - HANDBOOK REGISTER (30 books)
A3: Standalone company register. Source of truth for this entity. Update Current Status here; the Dashboard recalculates automatically.
A5: Book ID | B5: Book Title | C5: Brand / Division | D5: Department | E5: Book Category | F5: Employee Level Access | G5: Confidentiality Level | H5: Book Owner | I5: HR Review Required | J5: Legal Review Required | K5: Management Approval Required | L5: Employee Acknowledgement Required | M5: Quiz / Assessment Required | N5: Passing Score | O5: Related SD Academy Course ID | P5: SD Academy Folder Path | Q5: PDF File Name | R5: Version Number | S5: Current Status | T5: Priority | U5: Production Wave | V5: Review Frequency | W5: Next Review Due Date | X5: Remarks / Gap Notes
A6: CM-CMN-01 | B6: SD Group Common Employee Handbook | C6: Group Common | D6: All Departments | E6: Common Handbook | F6: L1-L5 | G6: Internal | H6: Group HR | I6: Yes | J6: Yes | K6: Yes | L6: Yes | M6: No | N6: - | O6: SDA-CRS-CM-CMN-01 | P6: SD Academy/01_Common_SD_Group | Q6: SDG_Common_Employee_Handbook_L1-L5_V1.0.pdf | R6: 1 | S6: PDF Final Checked | T6: Critical | U6: Wave 1 | V6: Annual + on law change | W6: 46478 | X6: Was Employee Handbook; base book for every employee
A7: CM-CMN-02 | B7: HR Policy Handbook | C7: Group Common | D7: HR | E7: Common Handbook | F7: L1-L5 | G7: Internal | H7: Group HR | I7: Yes | J7: Yes | K7: Yes | L7: Yes | M7: No | N7: - | O7: SDA-CRS-CM-CMN-02 | P7: SD Academy/01_Common_SD_Group | Q7: SDG_Common_HR_Policy_Handbook_L1-L5_V1.0.pdf | R7: 1 | S7: PDF Final Checked | T7: Critical | U7: Wave 1 | V7: Annual + on law change | W7: 46478
A8: CM-CMN-03 | B8: Attendance, Leave, Permission & Working Hours Handbook | C8: Group Common | D8: HR | E8: Common Handbook | F8: L1-L5 | G8: Internal | H8: Group HR | I8: Yes | J8: Yes | K8: Yes | L8: Yes | M8: No | N8: - | O8: SDA-CRS-CM-CMN-03 | P8: SD Academy/01_Common_SD_Group | Q8: SDG_Common_Attendance_Leave_Permission_Working_Hours_Handbook_L1-L5_V1.0.pdf | R8: 1 | S8: PDF Final Checked | T8: Critical | U8: Wave 1 | V8: Annual + on law change | W8: 46478
A9: CM-CMN-04 | B9: EHS Basics Handbook | C9: Group Common | D9: EHS | E9: Common Handbook | F9: L1-L5 | G9: Internal | H9: Group HR | I9: Yes | J9: Yes | K9: Yes | L9: Yes | M9: Yes | N9: 80 | O9: SDA-CRS-CM-CMN-04 | P9: SD Academy/01_Common_SD_Group | Q9: SDG_Common_EHS_Basics_Handbook_L1-L5_V1.0.pdf | R9: 1 | S9: PDF Final Checked | T9: Critical | U9: Wave 1 | V9: Annual + on law change | W9: 46478 | X9: Safety basics for all; site/factory detail in company SOP books
A10: CM-CMN-05 | B10: Information Security Handbook | C10: Group Common | D10: IT | E10: Common Handbook | F10: L1-L5 | G10: Internal | H10: Group HR | I10: Yes | J10: Yes | K10: Yes | L10: Yes | M10: Yes | N10: 80 | O10: SDA-CRS-CM-CMN-05 | P10: SD Academy/01_Common_SD_Group | Q10: SDG_Common_Information_Security_Handbook_L1-L5_V1.0.pdf | R10: 1 | S10: PDF Final Checked | T10: Critical | U10: Wave 1 | V10: Annual + on law change | W10: 46478
A11: CM-CMN-06 | B11: IT Asset, Device, Email & Software Usage Handbook | C11: Group Common | D11: IT | E11: Common Handbook | F11: L2-L5 | G11: Internal | H11: Group HR | I11: Yes | J11: Yes | K11: Yes | L11: Yes | M11: No | N11: - | O11: SDA-CRS-CM-CMN-06 | P11: SD Academy/01_Common_SD_Group | Q11: SDG_Common_IT_Asset_Device_Email_Software_Usage_Handbook_L2-L5_V1.0.pdf | R11: 1 | S11: PDF Final Checked | T11: Critical | U11: Wave 1 | V11: Annual + on law change | W11: 46478
A12: CM-CMN-07 | B12: Travel, Expense, Advance & Reimbursement Handbook | C12: Group Common | D12: Finance | E12: Common Handbook | F12: L2-L5 | G12: Internal | H12: Group HR | I12: Yes | J12: Yes | K12: Yes | L12: Yes | M12: No | N12: - | O12: SDA-CRS-CM-CMN-07 | P12: SD Academy/01_Common_SD_Group | Q12: SDG_Common_Travel_Expense_Advance_Reimbursement_Handbook_L2-L5_V1.0.pdf | R12: 1 | S12: PDF Final Checked | T12: Critical | U12: Wave 1 | V12: Annual + on law change | W12: 46478
A13: CM-CMN-08 | B13: Disciplinary Action, Notice Period & Exit Process Handbook | C13: Group Common | D13: HR | E13: Common Handbook | F13: L1-L5 | G13: Internal | H13: Group HR | I13: Yes | J13: Yes | K13: Yes | L13: Yes | M13: No | N13: - | O13: SDA-CRS-CM-CMN-08 | P13: SD Academy/01_Common_SD_Group | Q13: SDG_Common_Disciplinary_Action_Notice_Period_Exit_Process_Handbook_L1-L5_V1.0.pdf | R13: 1 | S13: PDF Final Checked | T13: Critical | U13: Wave 1 | V13: Annual + on law change | W13: 46478
A14: CM-CMN-09 | B14: Internal Communication, Email, WhatsApp & Meeting Discipline Handbook | C14: Group Common | D14: All Departments | E14: Common Handbook | F14: L1-L5 | G14: Internal | H14: Group HR | I14: Yes | J14: No | K14: Yes | L14: Yes | M14: No | N14: - | O14: SDA-CRS-CM-CMN-09 | P14: SD Academy/01_Common_SD_Group | Q14: SDG_Common_Internal_Communication_Email_WhatsApp_Meeting_Discipline_Handbook_L1-L5_V1.0.pdf | R14: 1 | S14: PDF Final Checked | T14: Critical | U14: Wave 1 | V14: Annual | W14: 46478 | X14: Mandated 5-13: channel discipline, escalation etiquette, meeting rules
A15: CM-CMN-10 | B15: Document Control, Records Management & Version Governance Handbook | C15: Group Common | D15: Quality | E15: Common Handbook | F15: L2-L5 | G15: Internal | H15: Group HR | I15: Yes | J15: No | K15: Yes | L15: Yes | M15: No | N15: - | O15: SDA-CRS-CM-CMN-10 | P15: SD Academy/01_Common_SD_Group | Q15: SDG_Common_Document_Control_Records_Management_Version_Governance_Handbook_L2-L5_V1.0.pdf | R15: 1 | S15: PDF Final Checked | T15: Critical | U15: Wave 1 | V15: Annual | W15: 46478 | X15: Mandated 5-14: numbering, retention, version governance for all records
A16: CM-CMN-11 | B16: IMS Handbook (ISO 9001/14001/45001) | C16: Group Common | D16: Quality | E16: Common Handbook | F16: L2-L5 | G16: Internal | H16: Group HR | I16: Yes | J16: No | K16: Yes | L16: Yes | M16: No | N16: - | O16: SDA-CRS-CM-CMN-11 | P16: SD Academy/01_Common_SD_Group | Q16: SDG_Common_IMS_Handbook_ISO_9001_14001_45001_L2-L5_V1.0.pdf | R16: 1 | S16: PDF Final Checked | T16: Critical | U16: Wave 1 | V16: Annual | W16: 46478 | X16: Retained: documentation standards feed all SOP books
A17: CM-CMN-13 | B17: Employee Acknowledgement and Policy Acceptance Handbook | C17: Group Common | D17: HR | E17: Common Handbook | F17: L1-L5 | G17: Internal | H17: Group HR | I17: Yes | J17: Yes | K17: Yes | L17: Yes | M17: No | N17: - | O17: SDA-CRS-CM-CMN-13 | P17: SD Academy/01_Common_SD_Group | Q17: SDG_Common_Employee_Acknowledgement_and_Policy_Acceptance_Handbook_L1-L5_V1.0.pdf | R17: 1 | S17: PDF Final Checked | T17: Critical | U17: Wave 1 | V17: Annual + on law change | W17: 46478 | X17: Mandated 5-17: how e-sign acknowledgement works and its legal standing
A18: CM-CMN-14 | B18: SD Academy Learning Access and Completion Handbook | C18: Group Common | D18: SD Academy | E18: Common Handbook | F18: L1-L5 | G18: Internal | H18: Group HR | I18: Yes | J18: No | K18: Yes | L18: Yes | M18: No | N18: - | O18: SDA-CRS-CM-CMN-14 | P18: SD Academy/01_Common_SD_Group | Q18: SDG_Common_Learning_Access_and_Completion_Handbook_L1-L5_V1.0.pdf | R18: 1 | S18: PDF Final Checked | T18: Critical | U18: Wave 1 | V18: Annual | W18: 46478 | X18: Was SD Academy Learning Handbook
A19: CM-CMP-01 | B19: Code of Conduct, Ethics & Business Integrity Handbook | C19: Group Common | D19: All Departments | E19: Compliance Handbook | F19: L1-L5 | G19: Internal | H19: Group HR | I19: Yes | J19: Yes | K19: Yes | L19: Yes | M19: Yes | N19: 80 | O19: SDA-CRS-CM-CMP-01 | P19: SD Academy/01_Common_SD_Group | Q19: SDG_Common_Code_of_Conduct_Ethics_Business_Integrity_Handbook_L1-L5_V1.0.pdf | R19: 1 | S19: PDF Final Checked | T19: Critical | U19: Wave 1 | V19: Annual + on law change | W19: 46478 | X19: Anti-bribery, COI, gifts, anti-fraud, whistle-blower, integrity
A20: CM-CMP-02 | B20: POSH Handbook | C20: Group Common | D20: HR | E20: Compliance Handbook | F20: L1-L5 | G20: Internal | H20: Group HR | I20: Yes | J20: Yes | K20: Yes | L20: Yes | M20: Yes | N20: 80 | O20: SDA-CRS-CM-CMP-02 | P20: SD Academy/01_Common_SD_Group | Q20: SDG_Common_POSH_Handbook_L1-L5_V1.0.pdf | R20: 1 | S20: PDF Final Checked | T20: Critical | U20: Wave 1 | V20: Annual + on law change | W20: 46478 | X20: POSH Act 2013; IC per location
A21: CM-CMP-03 | B21: Data Privacy, Consent & DPDP Compliance Handbook | C21: Group Common | D21: All Departments | E21: Compliance Handbook | F21: L2-L5 | G21: Internal | H21: Group HR | I21: Yes | J21: Yes | K21: Yes | L21: Yes | M21: Yes | N21: 80 | O21: SDA-CRS-CM-CMP-03 | P21: SD Academy/01_Common_SD_Group | Q21: SDG_Common_Data_Privacy_Consent_DPDP_Compliance_Handbook_L2-L5_V1.0.pdf | R21: 1 | S21: PDF Final Checked | T21: Critical | U21: Wave 1 | V21: Annual + on law change | W21: 46478 | X21: DPDP Act 2023 across employee/client/vendor/student/respondent data
A22: CM-CMP-04 | B22: Vendor, Supplier & Contractor Code of Conduct Handbook | C22: Group Common | D22: Procurement | E22: Compliance Handbook | F22: L2-L5 | G22: Controlled External | H22: Group HR | I22: Yes | J22: Yes | K22: Yes | L22: Yes | M22: Yes | N22: 80 | O22: SDA-CRS-CM-CMP-04 | P22: SD Academy/01_Common_SD_Group | Q22: SDG_Common_Vendor_Supplier_Contractor_Code_of_Conduct_Handbook_L2-L5_V1.0.pdf | R22: 1 | S22: PDF Final Checked | T22: Critical | U22: Wave 1 | V22: Annual + on law change | W22: 46478 | X22: Controlled external sharing with vendors
A23: CM-CMN-12 | B23: Performance Improvement Plan & Corrective Action Handbook | C23: Group Common | D23: HR | E23: Common Handbook | F23: L4-L5 | G23: Restricted | H23: Group HR | I23: Yes | J23: Yes | K23: Yes | L23: Yes | M23: No | N23: - | O23: SDA-CRS-CM-CMN-12 | P23: SD Academy/01_Common_SD_Group | Q23: SDG_Common_Performance_Improvement_Plan_Corrective_Action_Handbook_L4-L5_V1.0.pdf | R23: 1 | S23: PDF Final Checked | T23: High | U23: Wave 6 | V23: Annual + on law change | W23: 46478 | X23: Mandated 5-16: PIP stages, corrective action records
A24: CM-LDR-01 | B24: SD Group Leadership Principles Handbook | C24: Leadership & Management | D24: Leadership | E24: Leadership Handbook | F24: L1-L5 | G24: Internal | H24: Group CHRO Office | I24: Yes | J24: No | K24: Yes | L24: Yes | M24: No | N24: - | O24: SDA-CRS-CM-LDR-01 | P24: SD Academy/09_Leadership_Management | Q24: SDG_SDGroup_Leadership_Principles_Handbook_L1-L5_V1.0.pdf | R24: 1 | S24: PDF Final Checked | T24: High | U24: Wave 6 | V24: Annual | W24: 46478 | X24: Values-only edition; open to all levels
A25: CM-LDR-02 | B25: SD Group Leadership Operating Handbook | C25: Leadership & Management | D25: Leadership | E25: Leadership Handbook | F25: L5 | G25: Confidential | H25: Group CHRO Office | I25: Yes | J25: Yes | K25: Yes | L25: Yes | M25: No | N25: - | O25: SDA-CRS-CM-LDR-02 | P25: SD Academy/09_Leadership_Management | Q25: SDG_SDGroup_Leadership_Operating_Handbook_L5_V1.0.pdf | R25: 1 | S25: PDF Final Checked | T25: High | U25: Wave 6 | V25: Annual + on law change | W25: 46478 | X25: Authority, decision power, confidential governance - L5 only
A26: CM-LDR-03 | B26: Strategic Planning and Review Handbook | C26: Leadership & Management | D26: Leadership | E26: Leadership Handbook | F26: L5 | G26: Confidential | H26: Group CHRO Office | I26: Yes | J26: No | K26: Yes | L26: Yes | M26: No | N26: - | O26: SDA-CRS-CM-LDR-03 | P26: SD Academy/09_Leadership_Management | Q26: SDG_SDGroup_Strategic_Planning_and_Review_Handbook_L5_V1.0.pdf | R26: 1 | S26: PDF Final Checked | T26: High | U26: Wave 6 | V26: Annual | W26: 46478 | X26: Founder/director strategy - Confidential
A27: CM-MGT-01 | B27: SD Group Management Handbook | C27: Leadership & Management | D27: Management | E27: Management Handbook | F27: L4-L5 | G27: Restricted | H27: Group CHRO Office | I27: Yes | J27: No | K27: Yes | L27: Yes | M27: No | N27: - | O27: SDA-CRS-CM-MGT-01 | P27: SD Academy/09_Leadership_Management | Q27: SDG_SDGroup_Management_Handbook_L4-L5_V1.0.pdf | R27: 1 | S27: PDF Final Checked | T27: High | U27: Wave 6 | V27: Annual | W27: 46478 | X27: Group-level management operating standard
A28: CM-MGT-02 | B28: Department HOD Handbook | C28: Leadership & Management | D28: Management | E28: Management Handbook | F28: L4-L5 | G28: Restricted | H28: Group CHRO Office | I28: Yes | J28: No | K28: Yes | L28: Yes | M28: No | N28: - | O28: SDA-CRS-CM-MGT-02 | P28: SD Academy/09_Leadership_Management | Q28: SDG_SDGroup_Department_HOD_Handbook_L4-L5_V1.0.pdf | R28: 1 | S28: PDF Final Checked | T28: High | U28: Wave 6 | V28: Annual | W28: 46478 | X28: Was Department HOD Operations Handbook
A29: CM-MGT-03 | B29: Team Leader Handbook | C29: Leadership & Management | D29: Management | E29: Management Handbook | F29: L3-L5 | G29: Internal | H29: Group CHRO Office | I29: Yes | J29: No | K29: Yes | L29: Yes | M29: No | N29: - | O29: SDA-CRS-CM-MGT-03 | P29: SD Academy/09_Leadership_Management | Q29: SDG_SDGroup_Team_Leader_Handbook_L3-L5_V1.0.pdf | R29: 1 | S29: PDF Final Checked | T29: High | U29: Wave 6 | V29: Annual | W29: 46478
A30: CM-MGT-04 | B30: Management Review & MIS Dashboard Handbook | C30: Leadership & Management | D30: Management | E30: Management Handbook | F30: L4-L5 | G30: Restricted | H30: Group CHRO Office | I30: Yes | J30: No | K30: Yes | L30: Yes | M30: No | N30: - | O30: SDA-CRS-CM-MGT-04 | P30: SD Academy/09_Leadership_Management | Q30: SDG_SDGroup_Management_Review_MIS_Dashboard_Handbook_L4-L5_V1.0.pdf | R30: 1 | S30: PDF Final Checked | T30: High | U30: Wave 6 | V30: Annual | W30: 46478 | X30: Was Review Dashboard & MIS; satisfies Management Review mandate
A31: CM-MGT-05 | B31: Performance Review & Appraisal Handbook | C31: Leadership & Management | D31: Management | E31: Management Handbook | F31: L4-L5 | G31: Restricted | H31: Group CHRO Office | I31: Yes | J31: Yes | K31: Yes | L31: Yes | M31: No | N31: - | O31: SDA-CRS-CM-MGT-05 | P31: SD Academy/09_Leadership_Management | Q31: SDG_SDGroup_Performance_Review_Appraisal_Handbook_L4-L5_V1.0.pdf | R31: 1 | S31: PDF Final Checked | T31: High | U31: Wave 6 | V31: Annual + on law change | W31: 46478
A32: CM-MGT-06 | B32: Delegation of Authority & Approval Matrix Handbook | C32: Leadership & Management | D32: Management | E32: Management Handbook | F32: L4-L5 | G32: Restricted | H32: Group CHRO Office | I32: Yes | J32: No | K32: Yes | L32: Yes | M32: No | N32: - | O32: SDA-CRS-CM-MGT-06 | P32: SD Academy/09_Leadership_Management | Q32: SDG_SDGroup_Delegation_of_Authority_Approval_Matrix_Handbook_L4-L5_V1.0.pdf | R32: 1 | S32: PDF Final Checked | T32: High | U32: Wave 6 | V32: Annual | W32: 46478 | X32: Single DoA book; also satisfies Common list item 15
A33: CM-MGT-07 | B33: Business Target Review Handbook | C33: Leadership & Management | D33: Management | E33: Management Handbook | F33: L4-L5 | G33: Restricted | H33: Group CHRO Office | I33: Yes | J33: No | K33: Yes | L33: Yes | M33: No | N33: - | O33: SDA-CRS-CM-MGT-07 | P33: SD Academy/09_Leadership_Management | Q33: SDG_SDGroup_Business_Target_Review_Handbook_L4-L5_V1.0.pdf | R33: 1 | S33: PDF Final Checked | T33: High | U33: Wave 6 | V33: Annual | W33: 46478
A34: CM-MGT-08 | B34: Risk and Corrective Action Handbook | C34: Leadership & Management | D34: Management | E34: Management Handbook | F34: L4-L5 | G34: Restricted | H34: Group CHRO Office | I34: Yes | J34: No | K34: Yes | L34: Yes | M34: No | N34: - | O34: SDA-CRS-CM-MGT-08 | P34: SD Academy/09_Leadership_Management | Q34: SDG_SDGroup_Risk_and_Corrective_Action_Handbook_L4-L5_V1.0.pdf | R34: 1 | S34: PDF Final Checked | T34: High | U34: Wave 6 | V34: Annual | W34: 46478
A35: CM-MGT-09 | B35: Internal Audit and Compliance Review Handbook | C35: Leadership & Management | D35: Management | E35: Management Handbook | F35: L4-L5 | G35: Restricted | H35: Group CHRO Office | I35: Yes | J35: No | K35: Yes | L35: Yes | M35: Yes | N35: 80 | O35: SDA-CRS-CM-MGT-09 | P35: SD Academy/09_Leadership_Management | Q35: SDG_SDGroup_Internal_Audit_and_Compliance_Review_Handbook_L4-L5_V1.0.pdf | R35: 1 | S35: PDF Final Checked | T35: High | U35: Wave 6 | V35: Annual | W35: 46478

Sheet Level_Matrix
A1: SD GROUP - EMPLOYEE HANDBOOK REGISTER
A2: COMMON SD GROUP - LEVEL MATRIX (L1-L5)
A3: Cumulative: each level includes every level below it. Yes = the book sits in that level's path for people in scope.
A5: Book ID | B5: Book Title | C5: Brand / Division | D5: Department | E5: Book Category | F5: Access Band | G5: Min Level | H5: L1 | I5: L2 | J5: L3 | K5: L4 | L5: L5
A6: CM-CMN-01 | B6: SD Group Common Employee Handbook | C6: Group Common | D6: All Departments | E6: Common Handbook | F6: L1-L5 | G6: L1 | H6: Yes | I6: Yes | J6: Yes | K6: Yes | L6: Yes
A7: CM-CMN-02 | B7: HR Policy Handbook | C7: Group Common | D7: HR | E7: Common Handbook | F7: L1-L5 | G7: L1 | H7: Yes | I7: Yes | J7: Yes | K7: Yes | L7: Yes
A8: CM-CMN-03 | B8: Attendance, Leave, Permission & Working Hours Handbook | C8: Group Common | D8: HR | E8: Common Handbook | F8: L1-L5 | G8: L1 | H8: Yes | I8: Yes | J8: Yes | K8: Yes | L8: Yes
A9: CM-CMN-04 | B9: EHS Basics Handbook | C9: Group Common | D9: EHS | E9: Common Handbook | F9: L1-L5 | G9: L1 | H9: Yes | I9: Yes | J9: Yes | K9: Yes | L9: Yes
A10: CM-CMN-05 | B10: Information Security Handbook | C10: Group Common | D10: IT | E10: Common Handbook | F10: L1-L5 | G10: L1 | H10: Yes | I10: Yes | J10: Yes | K10: Yes | L10: Yes
A11: CM-CMN-08 | B11: Disciplinary Action, Notice Period & Exit Process Handbook | C11: Group Common | D11: HR | E11: Common Handbook | F11: L1-L5 | G11: L1 | H11: Yes | I11: Yes | J11: Yes | K11: Yes | L11: Yes
A12: CM-CMN-09 | B12: Internal Communication, Email, WhatsApp & Meeting Discipline Handbook | C12: Group Common | D12: All Departments | E12: Common Handbook | F12: L1-L5 | G12: L1 | H12: Yes | I12: Yes | J12: Yes | K12: Yes | L12: Yes
A13: CM-CMN-13 | B13: Employee Acknowledgement and Policy Acceptance Handbook | C13: Group Common | D13: HR | E13: Common Handbook | F13: L1-L5 | G13: L1 | H13: Yes | I13: Yes | J13: Yes | K13: Yes | L13: Yes
A14: CM-CMN-14 | B14: SD Academy Learning Access and Completion Handbook | C14: Group Common | D14: SD Academy | E14: Common Handbook | F14: L1-L5 | G14: L1 | H14: Yes | I14: Yes | J14: Yes | K14: Yes | L14: Yes
A15: CM-CMP-01 | B15: Code of Conduct, Ethics & Business Integrity Handbook | C15: Group Common | D15: All Departments | E15: Compliance Handbook | F15: L1-L5 | G15: L1 | H15: Yes | I15: Yes | J15: Yes | K15: Yes | L15: Yes
A16: CM-CMP-02 | B16: POSH Handbook | C16: Group Common | D16: HR | E16: Compliance Handbook | F16: L1-L5 | G16: L1 | H16: Yes | I16: Yes | J16: Yes | K16: Yes | L16: Yes
... A35: CM-LDR-03 | B35: Strategic Planning and Review Handbook | C35: Leadership & Management | D35: Leadership | E35: Leadership Handbook | F35: L5 | G35: L5 | H35: - | I35: - | J35: - | K35: - | L35: Yes

Sheet Level_Guide
A1: SD GROUP - EMPLOYEE HANDBOOK REGISTER
A2: 5-LEVEL LEARNING STRUCTURE
A3: Levels define who reads what. Paths are cumulative.
A5: Level | B5: Level Name | C5: Typical Roles | D5: What This Level Adds | E5: Completion Gate | F5: Common SD Group books at this level
A6: L1 | B6: L1 - Foundation | C6: Trainee / Executive / Operator | D6: Group core conduct & safety, own company handbook, own department basics | E6: Induction: complete within 30 days of joining | F6: 12
A7: L2 | B7: L2 - Practitioner | C7: Senior Executive / Technician / Specialist | D7: Adds own-function SOPs: how the job is done to standard | E7: Complete before independent working / unsupervised sign-off | F7: 18
A8: L3 | B8: L3 - Senior / Coordinator | C8: Senior Specialist / Team Coordinator / Lead | D8: Adds compliance books, escalation ownership, audit-facing material | E8: Complete before holding escalation or client-facing authority | F8: 19
A9: L4 | B9: L4 - Manager / HOD | C9: Manager / Head of Department | D9: Adds the management set: DoA, MIS review, appraisal, risk, targets, HOD role | E9: Complete before confirmation in a people-management role | F9: 28
A10: L5 | B10: L5 - Leadership | C10: Company Head / Function Head / Management | D10: Adds leadership set: Leadership Operating and Strategic Planning & Review | E10: Complete within 90 days of appointment to leadership | F10: 30

Sheet Upload_Checklist
A1: SD GROUP - EMPLOYEE HANDBOOK REGISTER
A2: COMMON SD GROUP - SD ACADEMY WEBSITE UPLOAD CHECKLIST (30 books)
A3: Portal admin working sheet. Complete every tick column per book, then set Current Status in the Register to 'Uploaded to SD Academy' / 'Access Tagged'.
A5: A. PRE-UPLOAD STANDARDS - verify these before uploading any file
A6: 1. File is the FINAL branded PDF - entity logo on cover, corner logo and watermark on every interior page.
A7: 2. File name matches the 'PDF File Name' column EXACTLY (case, underscores and _V1.0.pdf suffix included).
A8: 3. Version block reads V1.0 | Effective 03-Jul-2026 | Next Review 01-Jul-2027 on the document control page.
A9: 4. Upload to the exact 'SD Academy Folder Path' shown - do not create new folders or rename existing ones.
A10: 5. Link the file to its 'Related SD Academy Course ID' before publishing.
A11: 6. Apply access tags exactly as the 'Access Tag' column states (company / division / level).
A12: 7. Where Quiz = Yes, attach the mapped quiz and set the pass mark to 80% before the book goes live.
A13: 8. Where Legal Review = Yes, confirm legal sign-off is recorded in the Register BEFORE upload.
... A17: B. PER-BOOK UPLOAD CHECKLIST
A18: # | B18: Book ID | C18: PDF File Name (exact) | D18: SD Academy Folder Path | E18: Course ID | F18: Access Tag (company | division | level) | G18: Quiz | H18: Ack | I18: Legal Sign-off Confirmed | J18: 1. File Uploaded | K18: 2. Folder Path Verified | L18: 3. Access Tags Applied | M18: 4. Course Linked | N18: 5. Quiz Attached | O18: 6. Live Link Tested | P18: 7. Ack Campaign Pushed | Q18: Uploaded By | R18: Upload Date | S18: Notes / Issues
A19: 1 | B19: CM-CMN-01 | C19: SDG_Common_Employee_Handbook_L1-L5_V1.0.pdf | D19: SD Academy/01_Common_SD_Group | E19: SDA-CRS-CM-CMN-01 | F19: Common SD Group | Group Common | L1-L5 | G19: No | H19: Yes | I19: REQUIRED | N19: n/a
A20: 2 | B20: CM-CMN-02 | C20: SDG_Common_HR_Policy_Handbook_L1-L5_V1.0.pdf | D20: SD Academy/01_Common_SD_Group | E20: SDA-CRS-CM-CMN-02 | F20: Common SD Group | Group Common | L1-L5 | G20: No | H20: Yes | I20: REQUIRED | N20: n/a
A21: 3 | B21: CM-CMN-03 | C21: SDG_Common_Attendance_Leave_Permission_Working_Hours_Handbook_L1-L5_V1.0.pdf | D21: SD Academy/01_Common_SD_Group | E21: SDA-CRS-CM-CMN-03 | F21: Common SD Group | Group Common | L1-L5 | G21: No | H21: Yes | I21: REQUIRED | N21: n/a
A22: 4 | B22: CM-CMN-04 | C22: SDG_Common_EHS_Basics_Handbook_L1-L5_V1.0.pdf | D22: SD Academy/01_Common_SD_Group | E22: SDA-CRS-CM-CMN-04 | F22: Common SD Group | Group Common | L1-L5 | G22: Yes | H22: Yes | I22: REQUIRED
A23: 5 | B23: CM-CMN-05 | C23: SDG_Common_Information_Security_Handbook_L1-L5_V1.0.pdf | D23: SD Academy/01_Common_SD_Group | E23: SDA-CRS-CM-CMN-05 | F23: Common SD Group | Group Common | L1-L5 | G23: Yes | H23: Yes | I23: REQUIRED
A24: 6 | B24: CM-CMN-06 | C24: SDG_Common_IT_Asset_Device_Email_Software_Usage_Handbook_L2-L5_V1.0.pdf | D24: SD Academy/01_Common_SD_Group | E24: SDA-CRS-CM-CMN-06 | F24: Common SD Group | Group Common | L2-L5 | G24: No | H24: Yes | I24: REQUIRED | N24: n/a
A25: 7 | B25: CM-CMN-07 | C25: SDG_Common_Travel_Expense_Advance_Reimbursement_Handbook_L2-L5_V1.0.pdf | D25: SD Academy/01_Common_SD_Group | E25: SDA-CRS-CM-CMN-07 | F25: Common SD Group | Group Common | L2-L5 | G25: No | H25: Yes | I25: REQUIRED | N25: n/a
A26: 8 | B26: CM-CMN-08 | C26: SDG_Common_Disciplinary_Action_Notice_Period_Exit_Process_Handbook_L1-L5_V1.0.pdf | D26: SD Academy/01_Common_SD_Group | E26: SDA-CRS-CM-CMN-08 | F26: Common SD Group | Group Common | L1-L5 | G26: No | H26: Yes | I26: REQUIRED | N26: n/a
A27: 9 | B27: CM-CMN-09 | C27: SDG_Common_Internal_Communication_Email_WhatsApp_Meeting_Discipline_Handbook_L1-L5_V1.0.pdf | D27: SD Academy/01_Common_SD_Group | E27: SDA-CRS-CM-CMN-09 | F27: Common SD Group | Group Common | L1-L5 | G27: No | H27: Yes | I27: n/a | N27: n/a
A28: 10 | B28: CM-CMN-10 | C28: SDG_Common_Document_Control_Records_Management_Version_Governance_Handbook_L2-L5_V1.0.pdf | D28: SD Academy/01_Common_SD_Group | E28: SDA-CRS-CM-CMN-10 | F28: Common SD Group | Group Common | L2-L5 | G28: No | H28: Yes | I28: n/a | N28: n/a
A29: 11 | B29: CM-CMN-11 | C29: SDG_Common_IMS_Handbook_ISO_9001_14001_45001_L2-L5_V1.0.pdf | D29: SD Academy/01_Common_SD_Group | E29: SDA-CRS-CM-CMN-11 | F29: Common SD Group | Group Common | L2-L5 | G29: No | H29: Yes | I29: n/a | N29: n/a
A30: 12 | B30: CM-CMN-13 | C30: SDG_Common_Employee_Acknowledgement_and_Policy_Acceptance_Handbook_L1-L5_V1.0.pdf | D30: SD Academy/01_Common_SD_Group | E30: SDA-CRS-CM-CMN-13 | F30: Common SD Group | Group Common | L1-L5 | G30: No | H30: Yes | I30: REQUIRED | N30: n/a
A31: 13 | B31: CM-CMN-14 | C31: SDG_Common_Learning_Access_and_Completion_Handbook_L1-L5_V1.0.pdf | D31: SD Academy/01_Common_SD_Group | E31: SDA-CRS-CM-CMN-14 | F31: Common SD Group | Group Common | L1-L5 | G31: No | H31: Yes | I31: n/a | N31: n/a
A32: 14 | B32: CM-CMP-01 | C32: SDG_Common_Code_of_Conduct_Ethics_Business_Integrity_Handbook_L1-L5_V1.0.pdf | D32: SD Academy/01_Common_SD_Group | E32: SDA-CRS-CM-CMP-01 | F32: Common SD Group | Group Common | L1-L5 | G32: Yes | H32: Yes | I32: REQUIRED
A33: 15 | B33: CM-CMP-02 | C33: SDG_Common_POSH_Handbook_L1-L5_V1.0.pdf | D33: SD Academy/01_Common_SD_Group | E33: SDA-CRS-CM-CMP-02 | F33: Common SD Group | Group Common | L1-L5 | G33: Yes | H33: Yes | I33: REQUIRED
A34: 16 | B34: CM-CMP-03 | C34: SDG_Common_Data_Privacy_Consent_DPDP_Compliance_Handbook_L2-L5_V1.0.pdf | D34: SD Academy/01_Common_SD_Group | E34: SDA-CRS-CM-CMP-03 | F34: Common SD Group | Group Common | L2-L5 | G34: Yes | H34: Yes | I34: REQUIRED
A35: 17 | B35: CM-CMP-04 | C35: SDG_Common_Vendor_Supplier_Contractor_Code_of_Conduct_Handbook_L2-L5_V1.0.pdf | D35: SD Academy/01_Common_SD_Group | E35: SDA-CRS-CM-CMP-04 | F35: Common SD Group | Group Common | L2-L5 | G35: Yes | H35: Yes | I35: REQUIRED
A36: 18 | B36: CM-CMN-12 | C36: SDG_Common_Performance_Improvement_Plan_Corrective_Action_Handbook_L4-L5_V1.0.pdf | D36: SD Academy/01_Common_SD_Group | E36: SDA-CRS-CM-CMN-12 | F36: Common SD Group | Group Common | L4-L5 | G36: No | H36: Yes | I36: REQUIRED | N36: n/a
A37: 19 | B37: CM-LDR-01 | C37: SDG_SDGroup_Leadership_Principles_Handbook_L1-L5_V1.0.pdf | D37: SD Academy/09_Leadership_Management | E37: SDA-CRS-CM-LDR-01 | F37: Common SD Group | Leadership & Management | L1-L5 | G37: No | H37: Yes | I37: n/a | N37: n/a
A38: 20 | B38: CM-LDR-02 | C38: SDG_SDGroup_Leadership_Operating_Handbook_L5_V1.0.pdf | D38: SD Academy/09_Leadership_Management | E38: SDA-CRS-CM-LDR-02 | F38: Common SD Group | Leadership & Management | L5 | G38: No | H38: Yes | I38: REQUIRED | N38: n/a
A39: 21 | B39: CM-LDR-03 | C39: SDG_SDGroup_Strategic_Planning_and_Review_Handbook_L5_V1.0.pdf | D39: SD Academy/09_Leadership_Management | E39: SDA-CRS-CM-LDR-03 | F39: Common SD Group | Leadership & Management | L5 | G39: No | H39: Yes | I39: n/a | N39: n/a
A40: 22 | B40: CM-MGT-01 | C40: SDG_SDGroup_Management_Handbook_L4-L5_V1.0.pdf | D40: SD Academy/09_Leadership_Management | E40: SDA-CRS-CM-MGT-01 | F40: Common SD Group | Leadership & Management | L4-L5 | G40: No | H40: Yes | I40: n/a | N40: n/a
A41: 23 | B41: CM-MGT-02 | C41: SDG_SDGroup_Department_HOD_Handbook_L4-L5_V1.0.pdf | D41: SD Academy/09_Leadership_Management | E41: SDA-CRS-CM-MGT-02 | F41: Common SD Group | Leadership & Management | L4-L5 | G41: No | H41: Yes | I41: n/a | N41: n/a
A42: 24 | B42: CM-MGT-03 | C42: SDG_SDGroup_Team_Leader_Handbook_L3-L5_V1.0.pdf | D42: SD Academy/09_Leadership_Management | E42: SDA-CRS-CM-MGT-03 | F42: Common SD Group | Leadership & Management | L3-L5 | G42: No | H42: Yes | I42: n/a | N42: n/a
A43: 25 | B43: CM-MGT-04 | C43: SDG_SDGroup_Management_Review_MIS_Dashboard_Handbook_L4-L5_V1.0.pdf | D43: SD Academy/09_Leadership_Management | E43: SDA-CRS-CM-MGT-04 | F43: Common SD Group | Leadership & Management | L4-L5 | G43: No | H43: Yes | I43: n/a | N43: n/a
A44: 26 | B44: CM-MGT-05 | C44: SDG_SDGroup_Performance_Review_Appraisal_Handbook_L4-L5_V1.0.pdf | D44: SD Academy/09_Leadership_Management | E44: SDA-CRS-CM-MGT-05 | F44: Common SD Group | Leadership & Management | L4-L5 | G44: No | H44: Yes | I44: REQUIRED | N44: n/a
...

Sheet Access_Matrix
A1: SD GROUP - EMPLOYEE HANDBOOK REGISTER
A2: ACCESS BAND REFERENCE
A3: What each access band is used for across SD Group.
A5: Access band | B5: Used for
A6: L1-L5 | B6: Common employee, code of conduct, attendance & leave, HR basics, company/division handbook, department execution, basic safety, basic training, acknowledgement books
A7: L2-L5 | B7: SOP-heavy, tool usage, department workflow, execution process, software books
A8: L3-L5 | B8: Senior coordination, client escalation, advanced reporting, commercial process, data quality, compliance process
A9: L4-L5 | B9: Management review, approval matrix, team monitoring, internal audit, escalation control, corrective action
A10: L5 | B10: Founder/director strategy, confidential strategy, restructuring, sensitive legal strategy, high-level governance

Sheet Status_Flow
A1: SD GROUP - EMPLOYEE HANDBOOK REGISTER
A2: STATUS FLOW - 15 STAGES
A3: Each book moves through these stages. Use the dropdown in Register.
A5: # | B5: Stage | C5: Gate owner | D5: Exit criteria
A6: 1 | B6: Not Started | C6: Register owner | D6: Data sheet received
A7: 2 | B7: Draft Content Created | C7: Book Owner | D7: Full draft on approved template
A8: 3 | B8: HR Review Pending | C8: Group HR | D8: Queued for HR check
A9: 4 | B9: HR Approved | C9: Group HR | D9: Policy consistency verified
A10: 5 | B10: Legal Review Pending | C10: Legal & Compliance | D10: Queued where Legal = Yes
A11: 6 | B11: Legal Approved | C11: Legal & Compliance | D11: Statutory sign-off recorded
A12: 7 | B12: Management Review Pending | C12: Brand Head / CHRO | D12: Queued for approval
A13: 8 | B13: Management Approved | C13: Brand Head / CHRO | D13: Signed approval in register
A14: 9 | B14: PDF Designed | C14: Design cell | D14: Branded PDF with footer + metadata
A15: 10 | B15: PDF Final Checked | C15: QC reviewer | D15: Proof-read; version block verified
A16: 11 | B16: Uploaded to SD Academy | C16: Portal admin | D16: Live in correct folder path
A17: 12 | B17: Access Tagged | C17: Portal admin | D17: Company/division/level/role tags applied
... A20: 15 | B20: Archived / Superseded | C20: Portal admin | D20: Old version moved to 12_Archived_Versions

Sheet Change_Log
A1: SD GROUP - EMPLOYEE HANDBOOK REGISTER
A2: CHANGE LOG
A3: Record every structural or status change to this register.
A5: Date | B5: Version | C5: Change Type | D5: Description | E5: By
A6: 23-Jul-2026 | B6: v1.0 | C6: Register split from group master - Common SD Group | D6: Common SD Group register separated from SDG_Handbook_Master_Register_v3.1 into a standalone workbook covering 30 books. All 30 handbooks produced as entity-branded, QC-audited PDFs; status 'PDF Final Checked'. Next stages: HR/Legal/Management sign-off, SD Academy upload, access tagging, acknowledgement campaign. | E6: Group HR

Sheet Lists
A1: Validation lists (do not delete)
A3: Status | B3: Access | C3: Yes/No
A4: Not Started | B4: L1-L5 | C4: Yes
A5: Draft Content Created | B5: L2-L5 | C5: No
A6: HR Review Pending | B6: L3-L5
A7: HR Approved | B7: L4-L5
A8: Legal Review Pending | B8: L5
A9: Legal Approved
A10: Management Review Pending
A11: Management Approved
A12: PDF Designed
A13: PDF Final Checked
A14: Uploaded to SD Academy
A15: Access Tagged
A16: Acknowledgement Campaign Live
A17: Employee Acknowledgement Completed
A18: Archived / Superseded
